<?xml version="1.0"?>
<robot name="myrtle">
  <link name="base_link">
    <visual>
      <geometry>
        <cylinder length="0.03" radius="0.1"/>
      </geometry>
    </visual>
  </link>
 <link name="f_r_wheel">
    <visual>
      <origin xyz="0 0 0" rpy="0 0 0" />
      <geometry>
          <cylinder length="0.006" radius="0.03" />
      </geometry>
      <material name="black"/>
    </visual>
  </link>
  <joint name="joint right wheel" type="continuous">
    <parent link="base_link"/>
    <child link="f_r_wheel"/>
    <origin xyz="0 0.057 0" rpy="0 -1.57 1.57" /> 
    <axis xyz="0 0 1" rpy="0 0 0" />
  </joint>
   

 <link name="f_l_wheel">
    <visual>
      <origin xyz="0 0 0" rpy="0 0 0" />
      <geometry>
          <cylinder length="0.006" radius="0.03" />
      </geometry>
      <material name="black"/>
    </visual>
  </link>
  <joint name="joint left wheel" type="continuous">
    <parent link="base_link"/>
    <child link="f_l_wheel"/>
    <origin xyz="0 -0.057 0" rpy="0 1.57 1.57" /> 
    <axis xyz="0 0 1" rpy="0 0 0" />
  </joint>
   










</robot>

